PS C:\Users\tjend\OneDrive\Documenten\myapi> & C:/Users/tjend/AppData/Local/Microsoft/WindowsApps/python3.10.exe c:/Users/tjend/OneDrive/Documenten/myapi/main.py
Traceback (most recent call last):
  File "c:\Users\tjend\OneDrive\Documenten\myapi\main.py", line 3, in <module>
    import models
  File "c:\Users\tjend\OneDrive\Documenten\myapi\models.py", line 2, in <module>
    from database import Base
ImportError: cannot import name 'Base' from 'database' (c:\Users\tjend\OneDrive\Documenten\myapi\database.py)
    from database import Base
ImportError: cannot import name 'Base' from 'database' (c:\Users\tjend\OneDrive\Documenten\myapi\database.py    from database import Base
ImportError: cannot import name 'Base' from 'database'    from database import Base
ImportError: cannot import name 'Base' from 'database' (c:\Users\tjend\OneDrive\Documenten\myapi\database.py    from database import Base
ImportError: cannot import name 'Base' from 'database' (c:\Users\tjend\OneDrive\Documenten\myapi\database.py    from database import Base
ImportError: cannot import name 'Base' from 'database'    from database import Base
ImportError: cannot import name 'Base' from 'database' (c:\Users\tjend\OneDrive\Documenten\myapi\database.py    from database import Base
ImportError: cannot import name 'Base' from 'database'    from database import Base
ImportError: cannot import name 'Base' from 'database'    from database import Base
    from database import Base
ImportError: cannot import name 'Base' from 'database'    from database import Base
    from database import Base
ImportError: cannot import name 'Base' from 'database' (c:\Users\tjend\OneDrive\Documenten\myapi\database.py)
PS C:\Users\tjend\OneDrive\Documenten\myapi> & C:/Users/tjend/AppData/Local/Microsoft/WindowsApps/python3.10.exe c:/Users/tjend/OneDrive/Documenten/myapi/models.py
Traceback (most recent call last):
  File "c:\Users\tjend\OneDrive\Documenten\myapi\models.py", line 2, in <module>
    from database import Base
ImportError: cannot import name 'Base' from 'database' (c:\Users\tjend\OneDrive\Documenten\myapi\database.py)
PS C:\Users\tjend\OneDrive\Documenten\myapi> & C:/Users/tjend/AppData/Local/Microsoft/WindowsApps/python3.10.exe c:/Users/tjend/OneDrive/Documenten/myapi/main.py 
Traceback (most recent call last):
  File "c:\Users\tjend\OneDrive\Documenten\myapi\main.py", line 3, in <module>
    import models
  File "c:\Users\tjend\OneDrive\Documenten\myapi\models.py", line 2, in <module>
    from database import Base
  File "c:\Users\tjend\OneDrive\Documenten\myapi\database.py", line 6, in <module>
    engine = create_engine('sqlte:///todo.db')        
  File "<string>", line 2, in create_engine
  File "C:\Users\tjend\AppData\Local\Packages\PythonSoftwareFoundation.Python.3.10_qbz5n2kfra8p0\LocalCache\local-packages\Python310\site-packages\sqlalchemy\util\deprecations.py", line 281, in warned
    return fn(*args, **kwargs)  # type: ignore[no-any-return]
  File "C:\Users\tjend\AppData\Local\Packages\PythonSoftwareFoundation.Python.3.10_qbz5n2kfra8p0\LocalCache\local-packages\Python310\site-packages\sqlalchemy\engine\create.py", line 550, in create_engine
    entrypoint = u._get_entrypoint()
  File "C:\Users\tjend\AppData\Local\Packages\PythonSoftwareFoundation.Python.3.10_qbz5n2kfra8p0\LocalCache\local-packages\Python310\site-packages\sqlalchemy\engine\url.py", line 758, in _get_entrypoint
    cls = registry.load(name)
  File "C:\Users\tjend\AppData\Local\Packages\PythonSoftwareFoundation.Python.3.10_qbz5n2kfra8p0\LocalCache\local-packages\Python310\site-packages\sqlalchemy\util\langhelpers.py", line 375, in load
    raise exc.NoSuchModuleError(
sqlalchemy.exc.NoSuchModuleError: Can't load plugin: sqlalchemy.dialects:sqlte
